<?xml version="1.0"?>
<robot name="cybertruck_wheels" xmlns:xacro="http://ros.org/wiki/xacro">

    <!-- Includes -->
    <xacro:include filename="$(find description)/urdf/constants.xacro"/>

    <!-- Wheel macro -->
    <xacro:macro name="Wheel" params="fb lr">
        <!-- Wheel link -->
        <link name="${fb}_${lr}_wheel_link">
            <visual>
                <origin xyz="0 0 0" rpy="0 0 0"/>
                <geometry>
                    <mesh filename="package://description/urdf/meshes/Wheel.stl" scale="0.001 0.001 0.001"/>
                </geometry>
            </visual>

            <collision>
                <origin xyz="0 0 0" rpy="0 0 0"/>
                <geometry>
                    <mesh filename="package://description/urdf/meshes/Wheel.stl" scale="0.001 0.001 0.001"/>
                </geometry>
            </collision>

            <inertial>
            <mass value="${wheel_mass}"/>
            <inertia ixx="${wheel_ixx}"  ixy="${wheel_ixy}"  ixz="${wheel_ixz}" 
                        iyy="${wheel_iyy}" iyz="${wheel_iyz}" izz="${wheel_izz}" />
            </inertial>
        </link>

        <!-- Wheel joint -->
        <joint name="${fb}_${lr}_wheel_joint" type="continuous">
            <parent link="body_link"/>
            <child link="${fb}_${lr}_wheel_link"/>
            <origin xyz="${front_wheel if fb == 'front' else back_wheel}
                    ${left_wheel if lr == 'left' else right_wheel} 
                    ${height_to_wheel}" rpy="0 0 0"/>
            <axis xyz="0 1 0"/>
        </joint>
    </xacro:macro>

    <!-- Instantiate wheels -->
    <xacro:Wheel fb="front" lr="left"/>
    <xacro:Wheel fb="front" lr="right"/>

    <xacro:Wheel fb="back" lr="left"/>
    <xacro:Wheel fb="back" lr="right"/>

</robot>